Workbook

Sheet Planting Calc
B2: Gneiss's Vintage Story Planting Estimator
B5: Year average | C5: 3
B6: Latitude | C6: 45 | G6: January | P6: February | Y6: March | AH6: April | AQ6: May | AZ6: June
B7: Rainfall % | C7: 0.8 | G7: 1 | H7: 2 | I7: 3 | J7: 4 | K7: 5 | L7: 6 | M7: 7 | N7: 8 | O7: 9 | P7: 1 | Q7: 2 | R7: 3 | S7: 4 | T7: 5 | U7: 6 | V7: 7 | W7: 8 | X7: 9 | Y7: 1 | Z7: 2 | AA7: 3 | AB7: 4 | AC7: 5 | AD7: 6 | AE7: 7 | AF7: 8 | AG7: 9 | AH7: 1 | AI7: 2 | AJ7: 3 | AK7: 4 | AL7: 5 | AM7: 6 | AN7: 7 | AO7: 8 | AP7: 9 | AQ7: 1 | AR7: 2 | AS7: 3 | AT7: 4 | AU7: 5 | AV7: 6 | AW7: 7 | AX7: 8 | AY7: 9 | AZ7: 1 | BA7: 2 | BB7: 3 | BC7: 4 | BD7: 5 | BE7: 6 | BF7: 7 | BG7: 8 | BH7: 9
B8: Growth Speed | C8: 0.98 | G8: =IF(AND(G$9<$C$14,G$10>$C$15),"R",IF(G$9<$C$14,"C","H")) -> C | H8: =IF(AND(H$9<$C$14,H$10>$C$15),"R",IF(H$9<$C$14,"C","H")) -> C | I8: =IF(AND(I$9<$C$14,I$10>$C$15),"R",IF(I$9<$C$14,"C","H")) -> C | J8: =IF(AND(J$9<$C$14,J$10>$C$15),"R",IF(J$9<$C$14,"C","H")) -> C | K8: =IF(AND(K$9<$C$14,K$10>$C$15),"R",IF(K$9<$C$14,"C","H")) -> C | L8: =IF(AND(L$9<$C$14,L$10>$C$15),"R",IF(L$9<$C$14,"C","H")) -> C | M8: =IF(AND(M$9<$C$14,M$10>$C$15),"R",IF(M$9<$C$14,"C","H")) -> C | N8: =IF(AND(N$9<$C$14,N$10>$C$15),"R",IF(N$9<$C$14,"C","H")) -> C | ... BH8: =IF(AND(BH$9<$C$14,BH$10>$C$15),"R",IF(BH$9<$C$14,"C","H")) -> R
B9: Noise Adjust | C9: 0 | F9: High | G9: ='Planting Maths'!B133 -> -4.3698879 | H9: ='Planting Maths'!C133 -> -4.4199486 | I9: ='Planting Maths'!D133 -> -4.4433211 | J9: ='Planting Maths'!E133 -> -4.4497456 | K9: ='Planting Maths'!F133 -> -4.4497456 | L9: ='Planting Maths'!G133 -> -4.4433211 | M9: ='Planting Maths'!H133 -> -4.4199486 | N9: ='Planting Maths'!I133 -> -4.3698879 | ... BH9: ='Planting Maths'!BC133 -> 27.884647
B10: Greenhouse+ | C10: Yes | F10: Low | G10: ='Planting Maths'!B132 -> -11.969888 | H10: ='Planting Maths'!C132 -> -12.019949 | I10: ='Planting Maths'!D132 -> -12.043321 | J10: ='Planting Maths'!E132 -> -12.049746 | K10: ='Planting Maths'!F132 -> -12.049746 | L10: ='Planting Maths'!G132 -> -12.043321 | M10: ='Planting Maths'!H132 -> -12.019949 | N10: ='Planting Maths'!I132 -> -11.969888 | ... BH10: ='Planting Maths'!BC132 -> 20.284647
G12: July | P12: August | Y12: September | AH12: October | AQ12: November | AZ12: December
B13: Crop | C13: Carrot | G13: 1 | H13: 2 | I13: 3 | J13: 4 | K13: 5 | L13: 6 | M13: 7 | N13: 8 | O13: 9 | P13: 1 | Q13: 2 | R13: 3 | S13: 4 | T13: 5 | U13: 6 | V13: 7 | W13: 8 | X13: 9 | Y13: 1 | Z13: 2 | AA13: 3 | AB13: 4 | AC13: 5 | AD13: 6 | AE13: 7 | AF13: 8 | AG13: 9 | AH13: 1 | AI13: 2 | AJ13: 3 | AK13: 4 | AL13: 5 | AM13: 6 | AN13: 7 | AO13: 8 | AP13: 9 | AQ13: 1 | AR13: 2 | AS13: 3 | AT13: 4 | AU13: 5 | AV13: 6 | AW13: 7 | AX13: 8 | AY13: 9 | AZ13: 1 | BA13: 2 | BB13: 3 | BC13: 4 | BD13: 5 | BE13: 6 | BF13: 7 | BG13: 8 | BH13: 9
B14: Crop Temp Max | C14: =HLOOKUP(C13,'Crop Data'!$B$1:$R$5,2, ) -> 32 | G14: =IF(AND(G$15<$C$14,G$16>$C$15),"R",IF(G$15<$C$14,"C","H")) -> R | H14: =IF(AND(H$15<$C$14,H$16>$C$15),"R",IF(H$15<$C$14,"C","H")) -> R | I14: =IF(AND(I$15<$C$14,I$16>$C$15),"R",IF(I$15<$C$14,"C","H")) -> R | J14: =IF(AND(J$15<$C$14,J$16>$C$15),"R",IF(J$15<$C$14,"C","H")) -> R | K14: =IF(AND(K$15<$C$14,K$16>$C$15),"R",IF(K$15<$C$14,"C","H")) -> R | L14: =IF(AND(L$15<$C$14,L$16>$C$15),"R",IF(L$15<$C$14,"C","H")) -> R | M14: =IF(AND(M$15<$C$14,M$16>$C$15),"R",IF(M$15<$C$14,"C","H")) -> R | N14: =IF(AND(N$15<$C$14,N$16>$C$15),"R",IF(N$15<$C$14,"C","H")) -> R | ... BH14: =IF(AND(BH$15<$C$14,BH$16>$C$15),"R",IF(BH$15<$C$14,"C","H")) -> C
B15: Crop Temp Min | C15: =HLOOKUP(C13,'Crop Data'!$B$1:$R$5,3) -> -10 | F15: High | G15: ='Planting Maths'!BD133 -> 27.969888 | H15: ='Planting Maths'!BE133 -> 28.019949 | I15: ='Planting Maths'!BF133 -> 28.043321 | J15: ='Planting Maths'!BG133 -> 28.049746 | K15: ='Planting Maths'!BH133 -> 28.049746 | L15: ='Planting Maths'!BI133 -> 28.043321 | M15: ='Planting Maths'!BJ133 -> 28.019949 | N15: ='Planting Maths'!BK133 -> 27.969888 | ... BH15: ='Planting Maths'!DE133 -> -4.2846475
B16: Used Nutrient | C16: =HLOOKUP(C13,'Crop Data'!$B$1:$R$5,4) -> K | F16: Low | G16: ='Planting Maths'!BD132 -> 20.369888 | H16: ='Planting Maths'!BE132 -> 20.419949 | I16: ='Planting Maths'!BF132 -> 20.443321 | J16: ='Planting Maths'!BG132 -> 20.449746 | K16: ='Planting Maths'!BH132 -> 20.449746 | L16: ='Planting Maths'!BI132 -> 20.443321 | M16: ='Planting Maths'!BJ132 -> 20.419949 | N16: ='Planting Maths'!BK132 -> 20.369888 | ... BH16: ='Planting Maths'!DE132 -> -11.884647
B17: Growth Time | C17: =HLOOKUP(C13,'Crop Data'!$B$1:$R$5,5) -> 10.8
B19: Instructions: Make a copy to your drive to edit and use. You will need to use the two commands /wgen pos climate to get the Year avg and rainfall % then /wgen pos latitude to get the latitude. These values are specific to the exact location and elevation you are standing at. Enter those values into the sheet. The growth speed only affects the displayed growth time in the below crop section. Insurance will add a buffer to the temps, there is a yearly and daily temp noise which is not accounted for here. If your crops are in a green house, select it to add +5 degrees. Dates in blue are too cold, and red are too hot for the selcted crop. Video with more instructions. https://youtu.be/Bmj_BEn0Hy4
B23: Port courtesy of Mytten

Sheet Crop Data
B1: Amaranth | C1: Bell Pepper | D1: Cabbage | E1: Carrot | F1: Cassava | G1: Flax | H1: Onion | I1: Parsnip | J1: Peanut | K1: Pineapple | L1: Pumpkin | M1: Rice | N1: Rye | O1: Soybean | P1: Spelt | Q1: Sunflower | R1: Turnip
A2: Max | B2: 42 | C2: 34 | D2: 35 | E2: 32 | F2: 44 | G2: 40 | H2: 40 | I2: 32 | J2: 42 | K2: 48 | L2: 40 | M2: 46 | N2: 27 | O2: 40 | P2: 40 | Q2: 40 | R2: 27
A3: Min | B3: 6 | C3: 8 | D3: -5 | E3: -10 | F3: 4 | G3: -5 | H3: -1 | I3: -10 | J3: 10 | K3: 6 | L3: -5 | M3: 8 | N3: -12 | O3: -5 | P3: -5 | Q3: -5 | R3: -5
A4: Nutrient | B4: N | C4: N | D4: N | E4: K | F4: K | G4: K | H4: P | I4: P | J4: P | K4: N | L4: P | M4: K | N4: N | O4: K | P4: N | Q4: N | R4: N
A5: Growth | B5: 18 | C5: 19.8 | D5: 13.5 | E5: 10.8 | F5: 45 | G5: 18 | H5: 16.65 | I5: 18 | J5: 22.5 | K5: 54 | L5: 15.3 | M5: 20.25 | N5: 18 | O5: 11.25 | P5: 18 | Q5: 16.65 | R5: 9

Sheet Planting Maths
A1: ='Planting Calc'!C5 -> 3 | B1: WorldGenTemperature | E1: heretemp | F1: =A1 -> 3
A2: ='Planting Calc'!C6 -> 45 | B2: latitude | F2: =A2/90 -> 0.5 | J2: Crop | K2: min temp | L2: max temp | M2: First Month | N2: First Day | O2: nutrient | P2: moisture | Q2: Last Month | R2: Last Day
B3: seasonalVariationAmplitude | F3: =ABS(F2)*65 -> 32.5 | J3: Flax | K3: -5 | L3: 40 | M3: {=INDEX(A17:A124, MATCH(1, G17:G124 > K3, 0))} -> 4 | N3: {=INDEX(B17:B124, MATCH(1, G17:G124 > K3, 0))} -> 1
E4: heretemp | F4: =F1-F3/2 -> -13.25 | L4: 4
B5: distanceToJanuary | K5: 3
B6: yearRel | C6: =((A7-1)*9+(A8))/108 -> 0.0092592593 | K6: 2
A7: 1 | B7: month | C7: =MIN(ABS(C6*12-0.5),12-ABS(C6*12-0.5)) -> 0.38888889 | D7: =C7/6 -> 0.064814815 | K7: 1
A8: 1 | B8: day | D8: =6*D7^5-15*D7^4+10*D7^3 -> 0.0024649867 | F8: =D8*F3 -> 0.080112068 | K8: 0
E9: heretemp | F9: =F4+F8 -> -13.169888 | K9: -1
A10: ='Planting Calc'!C7 -> 0.8 | B10: diurnalVariationAmplitude | F10: =18-(A10*13) -> 7.6 | K10: -2
A11: 12 | B11: time | C11: =MIN(ABS(4-(A11)),24-ABS(4-(A11))) -> 8 | D11: =C11/12 -> 0.66666667 | K11: -3
B12: distanceTo6Am | D12: =6*D11^5-15*D11^4+10*D11^3 -> 0.79012346 | E12: heretemp | F12: =F9+((D12-0.5)*F10) -> -10.96495 | L12: -4
G15: Estimated | J15: Actual yea 20 | N15: Export | W15: 50
A16: Month | B16: Day | C16: yearRel | D16: Dist to Jan | E16: Smoothed | F16: Seasonal Variation | G16: 4 | H16: 16 | J16: 4 | K16: 16 | N16: 4 | O16: 16 | R16: 4 | S16: 16 | U16: Month | V16: Day | W16: 4 | X16: 16
A17: 1 | B17: 1 | C17: =((A17-1)*9+(B17))/108 -> 0.0092592593 | D17: =MIN(ABS(C17*12-0.5),12-ABS(C17*12-0.5))/6 -> 0.064814815 | E17: =6*D17^5-15*D17^4+10*D17^3 -> 0.0024649867 | F17: =E17*F$3 -> 0.080112068 | G17: =$F$4+F17+(-0.5*$F$10) -> -16.969888 | H17: =$F$4+F17+(0.5*$F$10) -> -9.3698879 | J17: -16.1 | K17: -8.8 | L17: =G17-J17 -> -0.86988793 | M17: =H17-K17 -> -0.56988793 | N17: -23.55502 | O17: -5.273496 | P17: =G17-N17 -> 6.5851321 | Q17: =H17-O17 -> -4.0963919 | R17: =J17-N17 -> 7.45502 | S17: =K17-O17 -> -3.526504 | U17: 1 | V17: 1
A18: 1 | B18: 2 | C18: =((A18-1)*9+(B18))/108 -> 0.018518519 | D18: =MIN(ABS(C18*12-0.5),12-ABS(C18*12-0.5))/6 -> 0.046296296 | E18: =6*D18^5-15*D18^4+10*D18^3 -> 0.00092465735 | F18: =E18*F$3 -> 0.030051364 | G18: =$F$4+F18+(-0.5*$F$10) -> -17.019949 | H18: =$F$4+F18+(0.5*$F$10) -> -9.4199486 | J18: -16.2 | K18: -8.5 | L18: =G18-J18 -> -0.81994864 | M18: =H18-K18 -> -0.91994864 | N18: -22.688868 | O18: -6.099039 | P18: =G18-N18 -> 5.6689194 | Q18: =H18-O18 -> -3.3209096 | R18: =J18-N18 -> 6.488868 | S18: =K18-O18 -> -2.400961 | U18: 1 | V18: 2
A19: 1 | B19: 3 | C19: =((A19-1)*9+(B19))/108 -> 0.027777778 | D19: =MIN(ABS(C19*12-0.5),12-ABS(C19*12-0.5))/6 -> 0.027777778 | E19: =6*D19^5-15*D19^4+10*D19^3 -> 0.00020550332 | F19: =E19*F$3 -> 0.0066788579 | G19: =$F$4+F19+(-0.5*$F$10) -> -17.043321 | H19: =$F$4+F19+(0.5*$F$10) -> -9.4433211 | J19: -17.8 | K19: -7.3 | L19: =G19-J19 -> 0.75667886 | M19: =H19-K19 -> -2.1433211 | N19: -22.57214 | O19: -3.966759 | P19: =G19-N19 -> 5.5288189 | Q19: =H19-O19 -> -5.4765621 | R19: =J19-N19 -> 4.77214 | S19: =K19-O19 -> -3.333241 | U19: 1 | V19: 3
A20: 1 | B20: 4 | C20: =((A20-1)*9+(B20))/108 -> 0.037037037 | D20: =MIN(ABS(C20*12-0.5),12-ABS(C20*12-0.5))/6 -> 0.0092592593 | E20: =6*D20^5-15*D20^4+10*D20^3 -> 7.8284763e-06 | F20: =E20*F$3 -> 0.00025442548 | G20: =$F$4+F20+(-0.5*$F$10) -> -17.049746 | H20: =$F$4+F20+(0.5*$F$10) -> -9.4497456 | J20: -17 | K20: -7.6 | L20: =G20-J20 -> -0.049745575 | M20: =H20-K20 -> -1.8497456 | N20: -22.45352 | O20: -5.010637 | P20: =G20-N20 -> 5.4037744 | Q20: =H20-O20 -> -4.4391086 | R20: =J20-N20 -> 5.45352 | S20: =K20-O20 -> -2.589363 | U20: 1 | V20: 4
A21: 1 | B21: 5 | C21: =((A21-1)*9+(B21))/108 -> 0.046296296 | D21: =MIN(ABS(C21*12-0.5),12-ABS(C21*12-0.5))/6 -> 0.0092592593 | E21: =6*D21^5-15*D21^4+10*D21^3 -> 7.8284763e-06 | F21: =E21*F$3 -> 0.00025442548 | G21: =$F$4+F21+(-0.5*$F$10) -> -17.049746 | H21: =$F$4+F21+(0.5*$F$10) -> -9.4497456 | J21: -17.5 | K21: -8.7 | L21: =G21-J21 -> 0.45025443 | M21: =H21-K21 -> -0.74974557 | N21: -24.627691 | O21: -4.686217 | P21: =G21-N21 -> 7.5779454 | Q21: =H21-O21 -> -4.7635286 | R21: =J21-N21 -> 7.127691 | S21: =K21-O21 -> -4.013783 | U21: 1 | V21: 5
A22: 1 | B22: 6 | C22: =((A22-1)*9+(B22))/108 -> 0.055555556 | D22: =MIN(ABS(C22*12-0.5),12-ABS(C22*12-0.5))/6 -> 0.027777778 | E22: =6*D22^5-15*D22^4+10*D22^3 -> 0.00020550332 | F22: =E22*F$3 -> 0.0066788579 | G22: =$F$4+F22+(-0.5*$F$10) -> -17.043321 | H22: =$F$4+F22+(0.5*$F$10) -> -9.4433211 | J22: -16.3 | K22: -8.5 | L22: =G22-J22 -> -0.74332114 | M22: =H22-K22 -> -0.94332114 | N22: -23.065195 | O22: -4.5814366 | P22: =G22-N22 -> 6.0218739 | Q22: =H22-O22 -> -4.8618845 | R22: =J22-N22 -> 6.765195 | S22: =K22-O22 -> -3.9185634 | U22: 1 | V22: 6
A23: 1 | B23: 7 | C23: =((A23-1)*9+(B23))/108 -> 0.064814815 | D23: =MIN(ABS(C23*12-0.5),12-ABS(C23*12-0.5))/6 -> 0.046296296 | E23: =6*D23^5-15*D23^4+10*D23^3 -> 0.00092465735 | F23: =E23*F$3 -> 0.030051364 | G23: =$F$4+F23+(-0.5*$F$10) -> -17.019949 | H23: =$F$4+F23+(0.5*$F$10) -> -9.4199486 | J23: -17 | K23: -8 | L23: =G23-J23 -> -0.019948636 | M23: =H23-K23 -> -1.4199486 | N23: -23.614023 | O23: -5.150031 | P23: =G23-N23 -> 6.5940744 | Q23: =H23-O23 -> -4.2699176 | R23: =J23-N23 -> 6.614023 | S23: =K23-O23 -> -2.849969 | U23: 1 | V23: 7
A24: 1 | B24: 8 | C24: =((A24-1)*9+(B24))/108 -> 0.074074074 | D24: =MIN(ABS(C24*12-0.5),12-ABS(C24*12-0.5))/6 -> 0.064814815 | E24: =6*D24^5-15*D24^4+10*D24^3 -> 0.0024649867 | F24: =E24*F$3 -> 0.080112068 | G24: =$F$4+F24+(-0.5*$F$10) -> -16.969888 | H24: =$F$4+F24+(0.5*$F$10) -> -9.3698879 | J24: -16.8 | K24: -7.8 | L24: =G24-J24 -> -0.16988793 | M24: =H24-K24 -> -1.5698879 | N24: -23.33651 | O24: -4.3843427 | P24: =G24-N24 -> 6.3666221 | Q24: =H24-O24 -> -4.9855452 | R24: =J24-N24 -> 6.53651 | S24: =K24-O24 -> -3.4156573 | U24: 1 | V24: 8
A25: 1 | B25: 9 | C25: =((A25-1)*9+(B25))/108 -> 0.083333333 | D25: =MIN(ABS(C25*12-0.5),12-ABS(C25*12-0.5))/6 -> 0.083333333 | E25: =6*D25^5-15*D25^4+10*D25^3 -> 0.0050877701 | F25: =E25*F$3 -> 0.16535253 | G25: =$F$4+F25+(-0.5*$F$10) -> -16.884647 | H25: =$F$4+F25+(0.5*$F$10) -> -9.2846475 | J25: -17 | K25: -8.4 | L25: =G25-J25 -> 0.11535253 | M25: =H25-K25 -> -0.88464747 | N25: -22.306946 | O25: -3.3574955 | P25: =G25-N25 -> 5.4222985 | Q25: =H25-O25 -> -5.927152 | R25: =J25-N25 -> 5.306946 | S25: =K25-O25 -> -5.0425045 | U25: 1 | V25: 9
A26: 2 | B26: 1 | C26: =((A26-1)*9+(B26))/108 -> 0.092592593 | D26: =MIN(ABS(C26*12-0.5),12-ABS(C26*12-0.5))/6 -> 0.10185185 | E26: =6*D26^5-15*D26^4+10*D26^3 -> 0.0090174365 | F26: =E26*F$3 -> 0.29306669 | G26: =$F$4+F26+(-0.5*$F$10) -> -16.756933 | H26: =$F$4+F26+(0.5*$F$10) -> -9.1569333 | J26: -17 | K26: -7.9 | L26: =G26-J26 -> 0.24306669 | M26: =H26-K26 -> -1.2569333 | N26: -22.63052 | O26: -5.9518194 | P26: =G26-N26 -> 5.8735867 | Q26: =H26-O26 -> -3.2051139 | R26: =J26-N26 -> 5.63052 | S26: =K26-O26 -> -1.9481806 | U26: 2 | V26: 1
A27: 2 | B27: 2 | C27: =((A27-1)*9+(B27))/108 -> 0.10185185 | D27: =MIN(ABS(C27*12-0.5),12-ABS(C27*12-0.5))/6 -> 0.12037037 | E27: =6*D27^5-15*D27^4+10*D27^3 -> 0.014443134 | F27: =E27*F$3 -> 0.46940184 | G27: =$F$4+F27+(-0.5*$F$10) -> -16.580598 | H27: =$F$4+F27+(0.5*$F$10) -> -8.9805982 | J27: -16 | K27: -7.4 | L27: =G27-J27 -> -0.58059816 | M27: =H27-K27 -> -1.5805982 | N27: -22.800684 | O27: -4.8126225 | P27: =G27-N27 -> 6.2200858 | Q27: =H27-O27 -> -4.1679757 | R27: =J27-N27 -> 6.800684 | S27: =K27-O27 -> -2.5873775 | U27: 2 | V27: 2
A28: 2 | B28: 3 | C28: =((A28-1)*9+(B28))/108 -> 0.11111111 | D28: =MIN(ABS(C28*12-0.5),12-ABS(C28*12-0.5))/6 -> 0.13888889 | E28: =6*D28^5-15*D28^4+10*D28^3 -> 0.021520296 | F28: =E28*F$3 -> 0.69940962 | G28: =$F$4+F28+(-0.5*$F$10) -> -16.35059 | H28: =$F$4+F28+(0.5*$F$10) -> -8.7505904 | J28: -16.5 | K28: -7.9 | L28: =G28-J28 -> 0.14940962 | M28: =H28-K28 -> -0.85059038 | N28: -21.809416 | O28: -4.42865 | P28: =G28-N28 -> 5.4588256 | Q28: =H28-O28 -> -4.3219404 | R28: =J28-N28 -> 5.309416 | S28: =K28-O28 -> -3.47135 | U28: 2 | V28: 3
... A124: 12 | B124: 9 | C124: =((A124-1)*9+(B124))/108 -> 1 | D124: =MIN(ABS(C124*12-0.5),12-ABS(C124*12-0.5))/6 -> 0.083333333 | E124: =6*D124^5-15*D124^4+10*D124^3 -> 0.0050877701 | F124: =E124*F$3 -> 0.16535253 | G124: =$F$4+F124+(-0.5*$F$10) -> -16.884647 | H124: =$F$4+F124+(0.5*$F$10) -> -9.2846475 | J124: -17 | K124: -7.2 | L124: =G124-J124 -> 0.11535253 | M124: =H124-K124 -> -2.0846475 | N124: -20.27619 | O124: -2.2460833 | P124: =G124-N124 -> 3.3915425 | Q124: =H124-O124 -> -7.0385642 | R124: =J124-N124 -> 3.27619 | S124: =K124-O124 -> -4.9539167 | U124: 12 | V124: 9
A126: Month | B126: 1 | C126: 1 | D126: 1 | E126: 1 | F126: 1 | G126: 1 | H126: 1 | I126: 1 | J126: 1 | K126: 2 | L126: 2 | M126: 2 | N126: 2 | O126: 2 | P126: 2 | Q126: 2 | R126: 2 | S126: 2 | T126: 3 | U126: 3 | V126: 3 | W126: 3 | X126: 3 | Y126: 3 | Z126: 3 | AA126: 3 | AB126: 3 | AC126: 4 | AD126: 4 | AE126: 4 | AF126: 4 | AG126: 4 | AH126: 4 | AI126: 4 | AJ126: 4 | AK126: 4 | AL126: 5 | AM126: 5 | AN126: 5 | AO126: 5 | AP126: 5 | AQ126: 5 | AR126: 5 | AS126: 5 | AT126: 5 | AU126: 6 | AV126: 6 | AW126: 6 | AX126: 6 | AY126: 6 | AZ126: 6 | BA126: 6 | BB126: 6 | BC126: 6 | BD126: 7 | BE126: 7 | BF126: 7 | BG126: 7 | BH126: 7 | BI126: 7 | BJ126: 7 | BK126: 7 | BL126: 7 | BM126: 8 | BN126: 8 | BO126: 8 | BP126: 8 | BQ126: 8 | BR126: 8 | BS126: 8 | BT126: 8 | BU126: 8 | BV126: 9 | BW126: 9 | BX126: 9 | BY126: 9 | BZ126: 9 | CA126: 9 | CB126: 9 | CC126: 9 | CD126: 9 | CE126: 10 | CF126: 10 | CG126: 10 | CH126: 10 | CI126: 10 | CJ126: 10 | CK126: 10 | CL126: 10 | CM126: 10 | CN126: 11 | CO126: 11 | CP126: 11 | CQ126: 11 | CR126: 11 | CS126: 11 | CT126: 11 | CU126: 11 | CV126: 11 | CW126: 12 | CX126: 12 | CY126: 12 | CZ126: 12 | DA126: 12 | DB126: 12 | DC126: 12 | DD126: 12 | DE126: 12
A127: Day | B127: 1 | C127: 2 | D127: 3 | E127: 4 | F127: 5 | G127: 6 | H127: 7 | I127: 8 | J127: 9 | K127: 1 | L127: 2 | M127: 3 | N127: 4 | O127: 5 | P127: 6 | Q127: 7 | R127: 8 | S127: 9 | T127: 1 | U127: 2 | V127: 3 | W127: 4 | X127: 5 | Y127: 6 | Z127: 7 | AA127: 8 | AB127: 9 | AC127: 1 | AD127: 2 | AE127: 3 | AF127: 4 | AG127: 5 | AH127: 6 | AI127: 7 | AJ127: 8 | AK127: 9 | AL127: 1 | AM127: 2 | AN127: 3 | AO127: 4 | AP127: 5 | AQ127: 6 | AR127: 7 | AS127: 8 | AT127: 9 | AU127: 1 | AV127: 2 | AW127: 3 | AX127: 4 | AY127: 5 | AZ127: 6 | BA127: 7 | BB127: 8 | BC127: 9 | BD127: 1 | BE127: 2 | BF127: 3 | BG127: 4 | BH127: 5 | BI127: 6 | BJ127: 7 | BK127: 8 | BL127: 9 | BM127: 1 | BN127: 2 | BO127: 3 | BP127: 4 | BQ127: 5 | BR127: 6 | BS127: 7 | BT127: 8 | BU127: 9 | BV127: 1 | BW127: 2 | BX127: 3 | BY127: 4 | BZ127: 5 | CA127: 6 | CB127: 7 | CC127: 8 | CD127: 9 | CE127: 1 | CF127: 2 | CG127: 3 | CH127: 4 | CI127: 5 | CJ127: 6 | CK127: 7 | CL127: 8 | CM127: 9 | CN127: 1 | CO127: 2 | CP127: 3 | CQ127: 4 | CR127: 5 | CS127: 6 | CT127: 7 | CU127: 8 | CV127: 9 | CW127: 1 | CX127: 2 | CY127: 3 | CZ127: 4 | DA127: 5 | DB127: 6 | DC127: 7 | DD127: 8 | DE127: 9
A128: yearRel | B128: =((B126-1)*9+(B127))/108 -> 0.0092592593 | C128: =((C126-1)*9+(C127))/108 -> 0.018518519 | D128: =((D126-1)*9+(D127))/108 -> 0.027777778 | E128: =((E126-1)*9+(E127))/108 -> 0.037037037 | F128: =((F126-1)*9+(F127))/108 -> 0.046296296 | G128: =((G126-1)*9+(G127))/108 -> 0.055555556 | H128: =((H126-1)*9+(H127))/108 -> 0.064814815 | I128: =((I126-1)*9+(I127))/108 -> 0.074074074 | ... DE128: =((DE126-1)*9+(DE127))/108 -> 1
A129: Dist to Jan | B129: =MIN(ABS(B128*12-0.5),12-ABS(B128*12-0.5))/6 -> 0.064814815 | C129: =MIN(ABS(C128*12-0.5),12-ABS(C128*12-0.5))/6 -> 0.046296296 | D129: =MIN(ABS(D128*12-0.5),12-ABS(D128*12-0.5))/6 -> 0.027777778 | E129: =MIN(ABS(E128*12-0.5),12-ABS(E128*12-0.5))/6 -> 0.0092592593 | F129: =MIN(ABS(F128*12-0.5),12-ABS(F128*12-0.5))/6 -> 0.0092592593 | G129: =MIN(ABS(G128*12-0.5),12-ABS(G128*12-0.5))/6 -> 0.027777778 | H129: =MIN(ABS(H128*12-0.5),12-ABS(H128*12-0.5))/6 -> 0.046296296 | I129: =MIN(ABS(I128*12-0.5),12-ABS(I128*12-0.5))/6 -> 0.064814815 | ... DE129: =MIN(ABS(DE128*12-0.5),12-ABS(DE128*12-0.5))/6 -> 0.083333333
A130: Smoothed | B130: =6*B129^5-15*B129^4+10*B129^3 -> 0.0024649867 | C130: =6*C129^5-15*C129^4+10*C129^3 -> 0.00092465735 | D130: =6*D129^5-15*D129^4+10*D129^3 -> 0.00020550332 | E130: =6*E129^5-15*E129^4+10*E129^3 -> 7.8284763e-06 | F130: =6*F129^5-15*F129^4+10*F129^3 -> 7.8284763e-06 | G130: =6*G129^5-15*G129^4+10*G129^3 -> 0.00020550332 | H130: =6*H129^5-15*H129^4+10*H129^3 -> 0.00092465735 | I130: =6*I129^5-15*I129^4+10*I129^3 -> 0.0024649867 | ... DE130: =6*DE129^5-15*DE129^4+10*DE129^3 -> 0.0050877701
A131: Seasonal Variation | B131: =B130*$F$3 -> 0.080112068 | C131: =C130*$F$3 -> 0.030051364 | D131: =D130*$F$3 -> 0.0066788579 | E131: =E130*$F$3 -> 0.00025442548 | F131: =F130*$F$3 -> 0.00025442548 | G131: =G130*$F$3 -> 0.0066788579 | H131: =H130*$F$3 -> 0.030051364 | I131: =I130*$F$3 -> 0.080112068 | ... DE131: =DE130*$F$3 -> 0.16535253
A132: 0.16666667 | B132: =$F$4+B131+(-0.5*$F$10)+'Planting Calc'!$C$9+IF('Planting Calc'!$C$10="Yes",5,0) -> -11.969888 | C132: =$F$4+C131+(-0.5*$F$10)+'Planting Calc'!$C$9+IF('Planting Calc'!$C$10="Yes",5,0) -> -12.019949 | D132: =$F$4+D131+(-0.5*$F$10)+'Planting Calc'!$C$9+IF('Planting Calc'!$C$10="Yes",5,0) -> -12.043321 | E132: =$F$4+E131+(-0.5*$F$10)+'Planting Calc'!$C$9+IF('Planting Calc'!$C$10="Yes",5,0) -> -12.049746 | F132: =$F$4+F131+(-0.5*$F$10)+'Planting Calc'!$C$9+IF('Planting Calc'!$C$10="Yes",5,0) -> -12.049746 | G132: =$F$4+G131+(-0.5*$F$10)+'Planting Calc'!$C$9+IF('Planting Calc'!$C$10="Yes",5,0) -> -12.043321 | H132: =$F$4+H131+(-0.5*$F$10)+'Planting Calc'!$C$9+IF('Planting Calc'!$C$10="Yes",5,0) -> -12.019949 | I132: =$F$4+I131+(-0.5*$F$10)+'Planting Calc'!$C$9+IF('Planting Calc'!$C$10="Yes",5,0) -> -11.969888 | ... DE132: =$F$4+DE131+(-0.5*$F$10)+'Planting Calc'!$C$9+IF('Planting Calc'!$C$10="Yes",5,0) -> -11.884647
A133: 0.66666667 | B133: =$F$4+B131+(0.5*$F$10)+'Planting Calc'!$C$9+IF('Planting Calc'!$C$10="Yes",5,0) -> -4.3698879 | C133: =$F$4+C131+(0.5*$F$10)+'Planting Calc'!$C$9+IF('Planting Calc'!$C$10="Yes",5,0) -> -4.4199486 | D133: =$F$4+D131+(0.5*$F$10)+'Planting Calc'!$C$9+IF('Planting Calc'!$C$10="Yes",5,0) -> -4.4433211 | E133: =$F$4+E131+(0.5*$F$10)+'Planting Calc'!$C$9+IF('Planting Calc'!$C$10="Yes",5,0) -> -4.4497456 | F133: =$F$4+F131+(0.5*$F$10)+'Planting Calc'!$C$9+IF('Planting Calc'!$C$10="Yes",5,0) -> -4.4497456 | G133: =$F$4+G131+(0.5*$F$10)+'Planting Calc'!$C$9+IF('Planting Calc'!$C$10="Yes",5,0) -> -4.4433211 | H133: =$F$4+H131+(0.5*$F$10)+'Planting Calc'!$C$9+IF('Planting Calc'!$C$10="Yes",5,0) -> -4.4199486 | I133: =$F$4+I131+(0.5*$F$10)+'Planting Calc'!$C$9+IF('Planting Calc'!$C$10="Yes",5,0) -> -4.3698879 | ... DE133: =$F$4+DE131+(0.5*$F$10)+'Planting Calc'!$C$9+IF('Planting Calc'!$C$10="Yes",5,0) -> -4.2846475
K135: 45658 | L135: 45809
K136: 12 | L136: 12
J137: 25 | L137: 23.3
J138: 26 | K138: -9.9 | L138: 23.1
J139: 27 | K139: -10.9 | L139: 23.5
...
